<?xml version="1.0"?>
<robot name="dummy">

  <!-- Base Link (Body) -->
  <link name="body">
    <inertial>
      <mass value="1.0"/>
      <inertia ixx="0.1" ixy="0.0" ixz="0.0" iyy="0.1" iyz="0.0" izz="0.1"/>
    </inertial>
    <visual>
      <geometry>
        <box size="0.2 0.1 0.3"/>
      </geometry>
      <material name="blue">
        <color rgba="0 0 1 1"/>
      </material>
    </visual>
    <collision>
      <geometry>
        <box size="0.2 0.1 0.3"/>
      </geometry>
      <surface>
        <contact>
          <lateral_friction value="0.5"/>
          <rolling_friction value="0.001"/>
          <spinning_friction value="0.001"/>
          <contact_cfm value="0.00001"/>
          <contact_erp value="0.2"/>
        </contact>
      </surface>
    </collision>
  </link>

  <!-- Left Thigh -->
  <link name="left_thigh">
    <inertial>
      <mass value="0.5"/>
      <inertia ixx="0.01" ixy="0.0" ixz="0.0" iyy="0.01" iyz="0.0" izz="0.01"/>
    </inertial>
    <visual>
      <geometry>
        <cylinder radius="0.03" length="0.2"/>
      </geometry>
      <material name="green">
        <color rgba="0 1 0 1"/>
      </material>
    </visual>
    <collision>
      <geometry>
        <cylinder radius="0.03" length="0.2"/>
      </geometry>
      <surface>
        <contact>
          <lateral_friction value="0.5"/>
          <rolling_friction value="0.001"/>
          <spinning_friction value="0.001"/>
          <contact_cfm value="0.00001"/>
          <contact_erp value="0.2"/>
        </contact>
      </surface>
    </collision>
  </link>

  <!-- Left Shin -->
  <link name="left_shin">
    <inertial>
      <mass value="0.5"/>
      <inertia ixx="0.01" ixy="0.0" ixz="0.0" iyy="0.01" iyz="0.0" izz="0.01"/>
    </inertial>
    <visual>
      <geometry>
        <cylinder radius="0.03" length="0.2"/>
      </geometry>
      <material name="green">
        <color rgba="0 1 0 1"/>
      </material>
    </visual>
    <collision>
      <geometry>
        <cylinder radius="0.03" length="0.2"/>
      </geometry>
      <surface>
        <contact>
          <lateral_friction value="0.5"/>
          <rolling_friction value="0.001"/>
          <spinning_friction value="0.001"/>
          <contact_cfm value="0.00001"/>
          <contact_erp value="0.2"/>
        </contact>
      </surface>
    </collision>
  </link>

  <!-- Right Thigh -->
  <link name="right_thigh">
    <inertial>
      <mass value="0.5"/>
      <inertia ixx="0.01" ixy="0.0" ixz="0.0" iyy="0.01" iyz="0.0" izz="0.01"/>
    </inertial>
    <visual>
      <geometry>
        <cylinder radius="0.03" length="0.2"/>
      </geometry>
      <material name="red">
        <color rgba="1 0 0 1"/>
      </material>
    </visual>
    <collision>
      <geometry>
        <cylinder radius="0.03" length="0.2"/>
      </geometry>
      <surface>
        <contact>
          <lateral_friction value="0.5"/>
          <rolling_friction value="0.001"/>
          <spinning_friction value="0.001"/>
          <contact_cfm value="0.00001"/>
          <contact_erp value="0.2"/>
        </contact>
      </surface>
    </collision>
  </link>

  <!-- Right Shin -->
  <link name="right_shin">
    <inertial>
      <mass value="0.5"/>
      <inertia ixx="0.01" ixy="0.0" ixz="0.0" iyy="0.01" iyz="0.0" izz="0.01"/>
    </inertial>
    <visual>
      <geometry>
        <cylinder radius="0.03" length="0.2"/>
      </geometry>
      <material name="red">
        <color rgba="1 0 0 1"/>
      </material>
    </visual>
    <collision>
      <geometry>
        <cylinder radius="0.03" length="0.2"/>
      </geometry>
      <surface>
        <contact>
          <lateral_friction value="0.5"/>
          <rolling_friction value="0.001"/>
          <spinning_friction value="0.001"/>
          <contact_cfm value="0.00001"/>
          <contact_erp value="0.2"/>
        </contact>
      </surface>
    </collision>
  </link>

  <!-- Left Foot -->
  <link name="left_foot">
    <inertial>
      <mass value="0.2"/>
      <inertia ixx="0.01" ixy="0.0" ixz="0.0" iyy="0.01" iyz="0.0" izz="0.01"/>
    </inertial>
    <visual>
      <geometry>
        <cylinder radius="0.04" length="0.1"/>
      </geometry>
      <material name="green">
        <color rgba="0 1 0 1"/>
      </material>
    </visual>
    <collision>
      <geometry>
        <cylinder radius="0.04" length="0.1"/>
      </geometry>
      <surface>
        <contact>
          <lateral_friction value="0.5"/>
          <rolling_friction value="0.001"/>
          <spinning_friction value="0.001"/>
          <contact_cfm value="0.00001"/>
          <contact_erp value="0.2"/>
        </contact>
      </surface>
    </collision>
  </link>

  <!-- Right Foot -->
  <link name="right_foot">
    <inertial>
      <mass value="0.2"/>
      <inertia ixx="0.01" ixy="0.0" ixz="0.0" iyy="0.01" iyz="0.0" izz="0.01"/>
    </inertial>
    <visual>
      <geometry>
        <cylinder radius="0.04" length="0.1"/>
      </geometry>
      <material name="red">
        <color rgba="1 0 0 1"/>
      </material>
    </visual>
    <collision>
      <geometry>
        <cylinder radius="0.04" length="0.1"/>
      </geometry>
      <surface>
        <contact>
          <lateral_friction value="0.5"/>
          <rolling_friction value="0.001"/>
          <spinning_friction value="0.001"/>
          <contact_cfm value="0.00001"/>
          <contact_erp value="0.2"/>
        </contact>
      </surface>
    </collision>
  </link>

  <!-- Joints -->
  <joint name="left_hip" type="revolute">
    <parent link="body"/>
    <child link="left_thigh"/>
    <origin xyz="0.05 0.1 0" rpy="0 0 0"/>
    <axis xyz="0 0 1"/>
    <limit lower="-1.57" upper="1.57" effort="10" velocity="1"/>
  </joint>

  <joint name="left_knee" type="revolute">
    <parent link="left_thigh"/>
    <child link="left_shin"/>
    <origin xyz="0 -0.1 0" rpy="0 0 0"/>
    <axis xyz="0 0 1"/>
    <limit lower="0" upper="1.57" effort="10" velocity="1"/>
  </joint>

  <joint name="left_ankle" type="revolute">
    <parent link="left_shin"/>
    <child link="left_foot"/>
    <origin xyz="0 -0.1 0" rpy="0 0 0"/>
    <axis xyz="0 0 1"/>
    <limit lower="-1.57" upper="1.57" effort="10" velocity="1"/>
  </joint>

  <joint name="right_hip" type="revolute">
    <parent link="body"/>
    <child link="right_thigh"/>
    <origin xyz="-0.05 0.1 0" rpy="0 0 0"/>
    <axis xyz="0 0 1"/>
    <limit lower="-1.57" upper="1.57" effort="10" velocity="1"/>
  </joint>

  <joint name="right_knee" type="revolute">
    <parent link="right_thigh"/>
    <child link="right_shin"/>
    <origin xyz="0 -0.1 0" rpy="0 0 0"/>
    <axis xyz="0 0 1"/>
    <limit lower="0" upper="1.57" effort="10" velocity="1"/>
  </joint>

  <joint name="right_ankle" type="revolute">
    <parent link="right_shin"/>
    <child link="right_foot"/>
    <origin xyz="0 -0.1 0" rpy="0 0 0"/>
    <axis xyz="0 0 1"/>
    <limit lower="-1.57" upper="1.57" effort="10" velocity="1"/>
  </joint>

</robot>
