<?xml version="1.0" ?>
<robot name="biped_robot">
    <!-- Body -->
    <link name="base_link">
        <visual>
            <geometry>
                <box size="0.3 0.3 0.1" />
            </geometry>
        </visual>
    </link>

    <!-- 왼쪽 다리 관절 -->
    <link name="left_leg">
        <visual>
            <geometry>
                <cylinder radius="0.05" length="0.5" />
            </geometry>
        </visual>
    </link>

    <joint name="left_hip_joint" type="revolute">
        <parent link="base_link"/>
        <child link="left_leg"/>
        <axis xyz="0 1 0"/>
        <origin xyz="0.15 0 0" rpy="0 0 0"/>
    </joint>

    <link name="left_knee">
        <visual>
            <geometry>
                <cylinder radius="0.04" length="0.5" />
            </geometry>
        </visual>
    </link>

    <joint name="left_knee_joint" type="revolute">
        <parent link="left_leg"/>
        <child link="left_knee"/>
        <axis xyz="0 1 0"/>
        <origin xyz="0 0 -0.5" rpy="0 0 0"/>
    </joint>

    <link name="left_foot">
        <visual>
            <geometry>
                <box size="0.1 0.05 0.02" />
            </geometry>
        </visual>
    </link>

    <joint name="left_ankle_joint" type="revolute">
        <parent link="left_knee"/>
        <child link="left_foot"/>
        <axis xyz="1 0 0"/> <!-- 축을 앞뒤로 조정 -->
        <origin xyz="0 0 -0.3" rpy="0 0 0"/> <!-- 발을 살짝 높임 -->
    </joint>

    <!-- 오른쪽 다리 관절 -->
    <link name="right_leg">
        <visual>
            <geometry>
                <cylinder radius="0.05" length="0.5" />
            </geometry>
        </visual>
    </link>

    <joint name="right_hip_joint" type="revolute">
        <parent link="base_link"/>
        <child link="right_leg"/>
        <axis xyz="0 -1 0"/>
        <origin xyz="-0.15 0 0" rpy="0 0 0"/>
    </joint>

    <link name="right_knee">
        <visual>
            <geometry>
                <cylinder radius="0.04" length="0.5" />
            </geometry>
        </visual>
    </link>

    <joint name="right_knee_joint" type="revolute">
        <parent link="right_leg"/>
        <child link="right_knee"/>
        <axis xyz="0 -1 0"/>
        <origin xyz="0 0 -0.5" rpy="0 0 0"/>
    </joint>

    <link name="right_foot">
        <visual>
            <geometry>
                <box size="0.1 0.05 0.02" />
            </geometry>
        </visual>
    </link>

    <joint name="right_ankle_joint" type="revolute">
        <parent link="right_knee"/>
        <child link="right_foot"/>
        <axis xyz="1 0 0"/> <!-- 축을 앞뒤로 조정 -->
        <origin xyz="0 0 -0.3" rpy="0 0 0"/> <!-- 발을 살짝 높임 -->
    </joint>
</robot>
